[2024-04-15 09:42:30,690][root][INFO] - Command line args:

[2024-04-15 09:42:30,690][root][INFO] - Hydra and wandb output path: /Users/ajgeorge/python/sis/logs/2024-04-15/09-42-30
[2024-04-15 09:42:30,690][root][INFO] - Solver output path: /Users/ajgeorge/python/sis/logs/2024-04-15/09-42-30
[2024-04-15 09:42:38,045][root][INFO] - ---------------------------------------------------------------
[2024-04-15 09:42:38,047][root][INFO] - Run config:
wandb:
  project: sis
  resume: allow
  mode: run
  name: 2024-04-15/09-42-30,
  tags: []
  id: ddb3fb8a8c2a003e3274edd54f4ee077b72edae1e4a6a3a8d8501ce9ad4a3195
keops_build_path: /Users/ajgeorge/.cache/keops/unknown/2024-04-15/09-42-30
merge_wandb_resume_cfg: true
restore_ckpt_from_wandb: true
target:
  _target_: stint_sampler.targets.targets.gmm
  mean: 5.0
  var: 1.0
interpolant:
  _target_: stint_sampler.stint.linearInterpolant.linear
  type: sin
model:
  _target_: stint_sampler.models.scoreNets.DenseNet
  dim: 2
  features:
  - 20
  - 50
  - 200
  - 200
  - 50
seed: 1
T: 1.0
dim: 2
batch_size: 128
NtTrain: 100
epochs: 1000
epoch_steps: 4
learning_rate: 0.01
solver:
  _target_: stint_sampler.stint.sis.half_sis
sampler:
  Nsamples: 10000
  NtSampler: 1000
out_dir: /Users/ajgeorge/python/sis/logs/2024-04-15/09-42-30

[2024-04-15 09:42:38,047][root][INFO] - ---------------------------------------------------------------
[2024-04-15 09:42:38,981][jax._src.xla_bridge][INFO] - Unable to initialize backend 'cuda': module 'jaxlib.xla_extension' has no attribute 'GpuAllocatorConfig'
[2024-04-15 09:42:38,981][jax._src.xla_bridge][INFO] - Unable to initialize backend 'rocm': module 'jaxlib.xla_extension' has no attribute 'GpuAllocatorConfig'
[2024-04-15 09:42:38,983][jax._src.xla_bridge][INFO] - Unable to initialize backend 'tpu': INTERNAL: Failed to open libtpu.so: dlopen(libtpu.so, 0x0001): tried: 'libtpu.so' (no such file), '/System/Volumes/Preboot/Cryptexes/OSlibtpu.so' (no such file), '/Users/ajgeorge/anaconda3/envs/sis/lib/python3.11/site-packages/jaxlib/../../../libtpu.so' (no such file), '/Users/ajgeorge/anaconda3/envs/sis/bin/../lib/libtpu.so' (no such file), '/usr/lib/libtpu.so' (no such file, not in dyld cache), 'libtpu.so' (no such file), '/usr/local/lib/libtpu.so' (no such file), '/usr/lib/libtpu.so' (no such file, not in dyld cache)
[2024-04-15 09:42:39,100][root][INFO] - Checkpoint directory: /Users/ajgeorge/python/sis/logs/2024-04-15/09-42-30/ckpt
[2024-04-15 09:42:58,402][root][CRITICAL] - Error in call to target 'stint_sampler.stint.sis.half_sis':
InstantiationException("Error locating target 'stint_sampler.stint.linearInterpolant.linear', set env var HYDRA_FULL_ERROR=1 to see chained exception.\nfull_key: interpolant")
full_key: solver
Traceback (most recent call last):
  File "/Users/ajgeorge/anaconda3/envs/sis/lib/python3.11/site-packages/hydra/_internal/utils.py", line 644, in _locate
    obj = getattr(obj, part)
          ^^^^^^^^^^^^^^^^^^
AttributeError: module 'stint_sampler.stint' has no attribute 'linearInterpolant'

During handling of the above exception, another exception occurred:

Traceback (most recent call last):
  File "/Users/ajgeorge/anaconda3/envs/sis/lib/python3.11/site-packages/hydra/_internal/utils.py", line 650, in _locate
    obj = import_module(mod)
          ^^^^^^^^^^^^^^^^^^
  File "/Users/ajgeorge/anaconda3/envs/sis/lib/python3.11/importlib/__init__.py", line 126, in import_module
    return _bootstrap._gcd_import(name[level:], package, level)
           ^^^^^^^^^^^^^^^^^^^^^^^^^^^^^^^^^^^^^^^^^^^^^^^^^^^^
  File "<frozen importlib._bootstrap>", line 1204, in _gcd_import
  File "<frozen importlib._bootstrap>", line 1176, in _find_and_load
  File "<frozen importlib._bootstrap>", line 1140, in _find_and_load_unlocked
ModuleNotFoundError: No module named 'stint_sampler.stint.linearInterpolant'

The above exception was the direct cause of the following exception:

Traceback (most recent call last):
  File "/Users/ajgeorge/anaconda3/envs/sis/lib/python3.11/site-packages/hydra/_internal/instantiate/_instantiate2.py", line 134, in _resolve_target
    target = _locate(target)
             ^^^^^^^^^^^^^^^
  File "/Users/ajgeorge/anaconda3/envs/sis/lib/python3.11/site-packages/hydra/_internal/utils.py", line 653, in _locate
    raise ImportError(
ImportError: Error loading 'stint_sampler.stint.linearInterpolant.linear':
ModuleNotFoundError("No module named 'stint_sampler.stint.linearInterpolant'")
Are you sure that 'linearInterpolant' is importable from module 'stint_sampler.stint'?

The above exception was the direct cause of the following exception:

Traceback (most recent call last):
  File "/Users/ajgeorge/anaconda3/envs/sis/lib/python3.11/site-packages/hydra/_internal/instantiate/_instantiate2.py", line 92, in _call_target
    return _target_(*args, **kwargs)
           ^^^^^^^^^^^^^^^^^^^^^^^^^
  File "/Users/ajgeorge/python/sis/stint_sampler/stint/sis.py", line 104, in __init__
    self.intrplnt = linearInterpolant(*call(self.cfg.interpolant))
                                       ^^^^^^^^^^^^^^^^^^^^^^^^^^
  File "/Users/ajgeorge/anaconda3/envs/sis/lib/python3.11/site-packages/hydra/_internal/instantiate/_instantiate2.py", line 226, in instantiate
    return instantiate_node(
           ^^^^^^^^^^^^^^^^^
  File "/Users/ajgeorge/anaconda3/envs/sis/lib/python3.11/site-packages/hydra/_internal/instantiate/_instantiate2.py", line 333, in instantiate_node
    _target_ = _resolve_target(node.get(_Keys.TARGET), full_key)
               ^^^^^^^^^^^^^^^^^^^^^^^^^^^^^^^^^^^^^^^^^^^^^^^^^
  File "/Users/ajgeorge/anaconda3/envs/sis/lib/python3.11/site-packages/hydra/_internal/instantiate/_instantiate2.py", line 139, in _resolve_target
    raise InstantiationException(msg) from e
hydra.errors.InstantiationException: Error locating target 'stint_sampler.stint.linearInterpolant.linear', set env var HYDRA_FULL_ERROR=1 to see chained exception.
full_key: interpolant

The above exception was the direct cause of the following exception:

Traceback (most recent call last):
  File "/Users/ajgeorge/python/sis/main.py", line 72, in main
    sampler = instantiate(cfg.solver, cfg)
              ^^^^^^^^^^^^^^^^^^^^^^^^^^^^
  File "/Users/ajgeorge/anaconda3/envs/sis/lib/python3.11/site-packages/hydra/_internal/instantiate/_instantiate2.py", line 226, in instantiate
    return instantiate_node(
           ^^^^^^^^^^^^^^^^^
  File "/Users/ajgeorge/anaconda3/envs/sis/lib/python3.11/site-packages/hydra/_internal/instantiate/_instantiate2.py", line 347, in instantiate_node
    return _call_target(_target_, partial, args, kwargs, full_key)
           ^^^^^^^^^^^^^^^^^^^^^^^^^^^^^^^^^^^^^^^^^^^^^^^^^^^^^^^
  File "/Users/ajgeorge/anaconda3/envs/sis/lib/python3.11/site-packages/hydra/_internal/instantiate/_instantiate2.py", line 97, in _call_target
    raise InstantiationException(msg) from e
hydra.errors.InstantiationException: Error in call to target 'stint_sampler.stint.sis.half_sis':
InstantiationException("Error locating target 'stint_sampler.stint.linearInterpolant.linear', set env var HYDRA_FULL_ERROR=1 to see chained exception.\nfull_key: interpolant")
full_key: solver
