{'wandb': {'project': 'sis', 'resume': 'allow', 'mode': 'run', 'name': '2024-04-16/20-38-16,', 'tags': [], 'id': 'c6787e6f9312bfc97814b1f4b00a29bfed0e0fa71286afef3a0b0bfe9ed8bb89'}, 'keops_build_path': '/Users/ajgeorge/.cache/keops/unknown/2024-04-16/20-38-16', 'merge_wandb_resume_cfg': True, 'restore_ckpt_from_wandb': True, 'target': {'_target_': 'stint_sampler.targets.targets.gmm', 'd': 2, 'mean': 5.0, 'var': 0.3}, 'interpolant': {'_target_': 'stint_sampler.stint.linearInterpolants.linear', 'type': 'trig'}, 'model': {'_target_': 'stint_sampler.models.scoreNets.DISnet', 'dim': 2, 'width': 64}, 'hjb_solver': {'_target_': 'stint_sampler.hjb_solver.oc.oc'}, 'seed': 1, 'T': 1.0, 'dim': 2, 'eps0': 1e-05, 'eps1': 1e-05, 'batch_size': 128, 'log_interval': 10, 'eval_interval': 100, 'jit_lossFn': 1, 'train': {'NtTrain': 100, 'epochs': 2000, 'epoch_steps': 4, 'learning_rate': 0.01}, 'solver': {'_target_': 'stint_sampler.stint.sis.half_sis'}, 'sampler': {'Nsamples': 10000, 'NtSampler': 1000}, 'pde_solver': {'scale_init_train': 0.01}, 'eval': {'hist_dims': [0, 1]}, 'out_dir': '/Users/ajgeorge/python/sis/logs/2024-04-16/20-38-16'}
[2024-04-16 20:38:25,477][root][INFO] - ---------------------------------------------------------------
[2024-04-16 20:38:25,479][root][INFO] - Run config:
wandb:
  project: sis
  resume: allow
  mode: run
  name: 2024-04-16/20-38-16,
  tags: []
  id: c6787e6f9312bfc97814b1f4b00a29bfed0e0fa71286afef3a0b0bfe9ed8bb89
keops_build_path: /Users/ajgeorge/.cache/keops/unknown/2024-04-16/20-38-16
merge_wandb_resume_cfg: true
restore_ckpt_from_wandb: true
target:
  _target_: stint_sampler.targets.targets.gmm
  d: 2
  mean: 5.0
  var: 0.3
interpolant:
  _target_: stint_sampler.stint.linearInterpolants.linear
  type: trig
model:
  _target_: stint_sampler.models.scoreNets.DISnet
  dim: 2
  width: 64
hjb_solver:
  _target_: stint_sampler.hjb_solver.oc.oc
seed: 1
T: 1.0
dim: 2
eps0: 1.0e-05
eps1: 1.0e-05
batch_size: 128
log_interval: 10
eval_interval: 100
jit_lossFn: 1
train:
  NtTrain: 100
  epochs: 2000
  epoch_steps: 4
  learning_rate: 0.01
solver:
  _target_: stint_sampler.stint.sis.half_sis
sampler:
  Nsamples: 10000
  NtSampler: 1000
pde_solver:
  scale_init_train: 0.01
eval:
  hist_dims:
  - 0
  - 1
out_dir: /Users/ajgeorge/python/sis/logs/2024-04-16/20-38-16
[2024-04-16 20:38:25,480][root][INFO] - ---------------------------------------------------------------
[2024-04-16 20:38:27,200][jax._src.xla_bridge][INFO] - Unable to initialize backend 'cuda': module 'jaxlib.xla_extension' has no attribute 'GpuAllocatorConfig'
[2024-04-16 20:38:27,200][jax._src.xla_bridge][INFO] - Unable to initialize backend 'rocm': module 'jaxlib.xla_extension' has no attribute 'GpuAllocatorConfig'
[2024-04-16 20:38:27,204][jax._src.xla_bridge][INFO] - Unable to initialize backend 'tpu': INTERNAL: Failed to open libtpu.so: dlopen(libtpu.so, 0x0001): tried: 'libtpu.so' (no such file), '/System/Volumes/Preboot/Cryptexes/OSlibtpu.so' (no such file), '/Users/ajgeorge/anaconda3/envs/sis/lib/python3.11/site-packages/jaxlib/../../../libtpu.so' (no such file), '/Users/ajgeorge/anaconda3/envs/sis/bin/../lib/libtpu.so' (no such file), '/usr/lib/libtpu.so' (no such file, not in dyld cache), 'libtpu.so' (no such file), '/usr/local/lib/libtpu.so' (no such file), '/usr/lib/libtpu.so' (no such file, not in dyld cache)
[2024-04-16 20:38:27,393][root][INFO] - Checkpoint directory: /Users/ajgeorge/python/sis/logs/2024-04-16/20-38-16/ckpt
[2024-04-16 20:38:33,558][root][CRITICAL] - Error in call to target 'stint_sampler.stint.sis.half_sis':
ConfigValueError('Unions of containers are not supported:\nparent: Union[Type[Module], Scope, Type[_Sentinel]]\n    full_key: \n    object_type=None')
full_key: solver
Traceback (most recent call last):
  File "/Users/ajgeorge/anaconda3/envs/sis/lib/python3.11/site-packages/hydra/_internal/instantiate/_instantiate2.py", line 92, in _call_target
    return _target_(*args, **kwargs)
           ^^^^^^^^^^^^^^^^^^^^^^^^^
  File "/Users/ajgeorge/python/sis/stint_sampler/stint/sis.py", line 164, in __init__
    self.hjb_solver = instantiate(self.cfg.hjb_solver,cfg=self.cfg,pde=self.pde,model=self.velocity_model)
                      ^^^^^^^^^^^^^^^^^^^^^^^^^^^^^^^^^^^^^^^^^^^^^^^^^^^^^^^^^^^^^^^^^^^^^^^^^^^^^^^^^^^^
  File "/Users/ajgeorge/anaconda3/envs/sis/lib/python3.11/site-packages/hydra/_internal/instantiate/_instantiate2.py", line 218, in instantiate
    config = OmegaConf.merge(config, kwargs)
             ^^^^^^^^^^^^^^^^^^^^^^^^^^^^^^^
  File "/Users/ajgeorge/anaconda3/envs/sis/lib/python3.11/site-packages/omegaconf/omegaconf.py", line 273, in merge
    target.merge_with(*configs[1:])
  File "/Users/ajgeorge/anaconda3/envs/sis/lib/python3.11/site-packages/omegaconf/basecontainer.py", line 492, in merge_with
    self._format_and_raise(key=None, value=None, cause=e)
  File "/Users/ajgeorge/anaconda3/envs/sis/lib/python3.11/site-packages/omegaconf/base.py", line 231, in _format_and_raise
    format_and_raise(
  File "/Users/ajgeorge/anaconda3/envs/sis/lib/python3.11/site-packages/omegaconf/_utils.py", line 819, in format_and_raise
    _raise(ex, cause)
  File "/Users/ajgeorge/anaconda3/envs/sis/lib/python3.11/site-packages/omegaconf/_utils.py", line 797, in _raise
    raise ex.with_traceback(sys.exc_info()[2])  # set env var OC_CAUSE=1 for full trace
    ^^^^^^^^^^^^^^^^^^^^^^^^^^^^^^^^^^^^^^^^^^
  File "/Users/ajgeorge/anaconda3/envs/sis/lib/python3.11/site-packages/omegaconf/basecontainer.py", line 490, in merge_with
    self._merge_with(*others)
  File "/Users/ajgeorge/anaconda3/envs/sis/lib/python3.11/site-packages/omegaconf/basecontainer.py", line 511, in _merge_with
    other = _ensure_container(other, flags=my_flags)
            ^^^^^^^^^^^^^^^^^^^^^^^^^^^^^^^^^^^^^^^^
  File "/Users/ajgeorge/anaconda3/envs/sis/lib/python3.11/site-packages/omegaconf/_utils.py", line 952, in _ensure_container
    target = OmegaConf.create(target, flags=flags)
             ^^^^^^^^^^^^^^^^^^^^^^^^^^^^^^^^^^^^^
  File "/Users/ajgeorge/anaconda3/envs/sis/lib/python3.11/site-packages/omegaconf/omegaconf.py", line 178, in create
    return OmegaConf._create_impl(
           ^^^^^^^^^^^^^^^^^^^^^^^
  File "/Users/ajgeorge/anaconda3/envs/sis/lib/python3.11/site-packages/omegaconf/omegaconf.py", line 900, in _create_impl
    format_and_raise(node=None, key=None, value=None, msg=str(e), cause=e)
  File "/Users/ajgeorge/anaconda3/envs/sis/lib/python3.11/site-packages/omegaconf/_utils.py", line 819, in format_and_raise
    _raise(ex, cause)
  File "/Users/ajgeorge/anaconda3/envs/sis/lib/python3.11/site-packages/omegaconf/_utils.py", line 797, in _raise
    raise ex.with_traceback(sys.exc_info()[2])  # set env var OC_CAUSE=1 for full trace
    ^^^^^^^^^^^^^^^^^^^^^^^^^^^^^^^^^^^^^^^^^^
  File "/Users/ajgeorge/anaconda3/envs/sis/lib/python3.11/site-packages/omegaconf/omegaconf.py", line 861, in _create_impl
    return DictConfig(
           ^^^^^^^^^^^
  File "/Users/ajgeorge/anaconda3/envs/sis/lib/python3.11/site-packages/omegaconf/dictconfig.py", line 111, in __init__
    format_and_raise(node=None, key=key, value=None, cause=ex, msg=str(ex))
  File "/Users/ajgeorge/anaconda3/envs/sis/lib/python3.11/site-packages/omegaconf/_utils.py", line 819, in format_and_raise
    _raise(ex, cause)
  File "/Users/ajgeorge/anaconda3/envs/sis/lib/python3.11/site-packages/omegaconf/_utils.py", line 797, in _raise
    raise ex.with_traceback(sys.exc_info()[2])  # set env var OC_CAUSE=1 for full trace
    ^^^^^^^^^^^^^^^^^^^^^^^^^^^^^^^^^^^^^^^^^^
  File "/Users/ajgeorge/anaconda3/envs/sis/lib/python3.11/site-packages/omegaconf/dictconfig.py", line 109, in __init__
    self._set_value(content, flags=flags)
  File "/Users/ajgeorge/anaconda3/envs/sis/lib/python3.11/site-packages/omegaconf/dictconfig.py", line 647, in _set_value
    raise e
  File "/Users/ajgeorge/anaconda3/envs/sis/lib/python3.11/site-packages/omegaconf/dictconfig.py", line 644, in _set_value
    self._set_value_impl(value, flags)
  File "/Users/ajgeorge/anaconda3/envs/sis/lib/python3.11/site-packages/omegaconf/dictconfig.py", line 690, in _set_value_impl
    self.__setitem__(k, v)
  File "/Users/ajgeorge/anaconda3/envs/sis/lib/python3.11/site-packages/omegaconf/dictconfig.py", line 314, in __setitem__
    self._format_and_raise(key=key, value=value, cause=e)
  File "/Users/ajgeorge/anaconda3/envs/sis/lib/python3.11/site-packages/omegaconf/base.py", line 231, in _format_and_raise
    format_and_raise(
  File "/Users/ajgeorge/anaconda3/envs/sis/lib/python3.11/site-packages/omegaconf/_utils.py", line 819, in format_and_raise
    _raise(ex, cause)
  File "/Users/ajgeorge/anaconda3/envs/sis/lib/python3.11/site-packages/omegaconf/_utils.py", line 797, in _raise
    raise ex.with_traceback(sys.exc_info()[2])  # set env var OC_CAUSE=1 for full trace
    ^^^^^^^^^^^^^^^^^^^^^^^^^^^^^^^^^^^^^^^^^^
  File "/Users/ajgeorge/anaconda3/envs/sis/lib/python3.11/site-packages/omegaconf/dictconfig.py", line 308, in __setitem__
    self.__set_impl(key=key, value=value)
  File "/Users/ajgeorge/anaconda3/envs/sis/lib/python3.11/site-packages/omegaconf/dictconfig.py", line 318, in __set_impl
    self._set_item_impl(key, value)
  File "/Users/ajgeorge/anaconda3/envs/sis/lib/python3.11/site-packages/omegaconf/basecontainer.py", line 620, in _set_item_impl
    self._wrap_value_and_set(key, value, target_type_hint)
  File "/Users/ajgeorge/anaconda3/envs/sis/lib/python3.11/site-packages/omegaconf/basecontainer.py", line 628, in _wrap_value_and_set
    wrapped = _maybe_wrap(
              ^^^^^^^^^^^^
  File "/Users/ajgeorge/anaconda3/envs/sis/lib/python3.11/site-packages/omegaconf/omegaconf.py", line 1105, in _maybe_wrap
    return _node_wrap(
           ^^^^^^^^^^^
  File "/Users/ajgeorge/anaconda3/envs/sis/lib/python3.11/site-packages/omegaconf/omegaconf.py", line 1027, in _node_wrap
    node = DictConfig(
           ^^^^^^^^^^^
  File "/Users/ajgeorge/anaconda3/envs/sis/lib/python3.11/site-packages/omegaconf/dictconfig.py", line 111, in __init__
    format_and_raise(node=None, key=key, value=None, cause=ex, msg=str(ex))
  File "/Users/ajgeorge/anaconda3/envs/sis/lib/python3.11/site-packages/omegaconf/_utils.py", line 819, in format_and_raise
    _raise(ex, cause)
  File "/Users/ajgeorge/anaconda3/envs/sis/lib/python3.11/site-packages/omegaconf/_utils.py", line 797, in _raise
    raise ex.with_traceback(sys.exc_info()[2])  # set env var OC_CAUSE=1 for full trace
    ^^^^^^^^^^^^^^^^^^^^^^^^^^^^^^^^^^^^^^^^^^
  File "/Users/ajgeorge/anaconda3/envs/sis/lib/python3.11/site-packages/omegaconf/dictconfig.py", line 94, in __init__
    self._set_value(content, flags=flags)
  File "/Users/ajgeorge/anaconda3/envs/sis/lib/python3.11/site-packages/omegaconf/dictconfig.py", line 647, in _set_value
    raise e
  File "/Users/ajgeorge/anaconda3/envs/sis/lib/python3.11/site-packages/omegaconf/dictconfig.py", line 644, in _set_value
    self._set_value_impl(value, flags)
  File "/Users/ajgeorge/anaconda3/envs/sis/lib/python3.11/site-packages/omegaconf/dictconfig.py", line 674, in _set_value_impl
    data = get_structured_config_data(value, allow_objects=ao)
           ^^^^^^^^^^^^^^^^^^^^^^^^^^^^^^^^^^^^^^^^^^^^^^^^^^^
  File "/Users/ajgeorge/anaconda3/envs/sis/lib/python3.11/site-packages/omegaconf/_utils.py", line 495, in get_structured_config_data
    return get_dataclass_data(obj, allow_objects=allow_objects)
           ^^^^^^^^^^^^^^^^^^^^^^^^^^^^^^^^^^^^^^^^^^^^^^^^^^^^
  File "/Users/ajgeorge/anaconda3/envs/sis/lib/python3.11/site-packages/omegaconf/_utils.py", line 411, in get_dataclass_data
    format_and_raise(node=None, key=None, value=value, cause=e, msg=str(e))
  File "/Users/ajgeorge/anaconda3/envs/sis/lib/python3.11/site-packages/omegaconf/_utils.py", line 899, in format_and_raise
    _raise(ex, cause)
  File "/Users/ajgeorge/anaconda3/envs/sis/lib/python3.11/site-packages/omegaconf/_utils.py", line 797, in _raise
    raise ex.with_traceback(sys.exc_info()[2])  # set env var OC_CAUSE=1 for full trace
    ^^^^^^^^^^^^^^^^^^^^^^^^^^^^^^^^^^^^^^^^^^
omegaconf.errors.ConfigValueError: Unions of containers are not supported:
parent: Union[Type[Module], Scope, Type[_Sentinel]]
    full_key:
    object_type=None
The above exception was the direct cause of the following exception:
Traceback (most recent call last):
  File "/Users/ajgeorge/python/sis/main.py", line 72, in main
    sampler = instantiate(cfg.solver, cfg)
              ^^^^^^^^^^^^^^^^^^^^^^^^^^^^
  File "/Users/ajgeorge/anaconda3/envs/sis/lib/python3.11/site-packages/hydra/_internal/instantiate/_instantiate2.py", line 226, in instantiate
    return instantiate_node(
           ^^^^^^^^^^^^^^^^^
  File "/Users/ajgeorge/anaconda3/envs/sis/lib/python3.11/site-packages/hydra/_internal/instantiate/_instantiate2.py", line 347, in instantiate_node
    return _call_target(_target_, partial, args, kwargs, full_key)
           ^^^^^^^^^^^^^^^^^^^^^^^^^^^^^^^^^^^^^^^^^^^^^^^^^^^^^^^
  File "/Users/ajgeorge/anaconda3/envs/sis/lib/python3.11/site-packages/hydra/_internal/instantiate/_instantiate2.py", line 97, in _call_target
    raise InstantiationException(msg) from e
hydra.errors.InstantiationException: Error in call to target 'stint_sampler.stint.sis.half_sis':
ConfigValueError('Unions of containers are not supported:\nparent: Union[Type[Module], Scope, Type[_Sentinel]]\n    full_key: \n    object_type=None')
full_key: solver