{'wandb': {'project': 'sis', 'resume': 'allow', 'mode': 'run', 'name': '2024-04-15/09-51-02,', 'tags': [], 'id': 'ef35b00e73dd6e7a43be645652b529cff644d279537995af445050764d85d0f3'}, 'keops_build_path': '/Users/ajgeorge/.cache/keops/unknown/2024-04-15/09-51-02', 'merge_wandb_resume_cfg': True, 'restore_ckpt_from_wandb': True, 'target': {'_target_': 'stint_sampler.targets.targets.gmm', 'mean': 5.0, 'var': 1.0}, 'interpolant': {'_target_': 'stint_sampler.stint.linearInterpolants.linear', 'type': 'sin'}, 'model': {'_target_': 'stint_sampler.models.scoreNets.DenseNet', 'dim': 2, 'features': [20, 50, 200, 200, 50]}, 'seed': 1, 'T': 1.0, 'dim': 2, 'batch_size': 128, 'NtTrain': 100, 'epochs': 1000, 'epoch_steps': 4, 'learning_rate': 0.01, 'solver': {'_target_': 'stint_sampler.stint.sis.half_sis'}, 'sampler': {'Nsamples': 10000, 'NtSampler': 1000}, 'out_dir': '/Users/ajgeorge/python/sis/logs/2024-04-15/09-51-02'}
[2024-04-15 09:51:10,020][root][INFO] - ---------------------------------------------------------------
[2024-04-15 09:51:10,022][root][INFO] - Run config:
wandb:
  project: sis
  resume: allow
  mode: run
  name: 2024-04-15/09-51-02,
  tags: []
  id: ef35b00e73dd6e7a43be645652b529cff644d279537995af445050764d85d0f3
keops_build_path: /Users/ajgeorge/.cache/keops/unknown/2024-04-15/09-51-02
merge_wandb_resume_cfg: true
restore_ckpt_from_wandb: true
target:
  _target_: stint_sampler.targets.targets.gmm
  mean: 5.0
  var: 1.0
interpolant:
  _target_: stint_sampler.stint.linearInterpolants.linear
  type: sin
model:
  _target_: stint_sampler.models.scoreNets.DenseNet
  dim: 2
  features:
  - 20
  - 50
  - 200
  - 200
  - 50
seed: 1
T: 1.0
dim: 2
batch_size: 128
NtTrain: 100
epochs: 1000
epoch_steps: 4
learning_rate: 0.01
solver:
  _target_: stint_sampler.stint.sis.half_sis
sampler:
  Nsamples: 10000
  NtSampler: 1000
out_dir: /Users/ajgeorge/python/sis/logs/2024-04-15/09-51-02
[2024-04-15 09:51:10,022][root][INFO] - ---------------------------------------------------------------
[2024-04-15 09:51:10,951][jax._src.xla_bridge][INFO] - Unable to initialize backend 'cuda': module 'jaxlib.xla_extension' has no attribute 'GpuAllocatorConfig'
[2024-04-15 09:51:10,951][jax._src.xla_bridge][INFO] - Unable to initialize backend 'rocm': module 'jaxlib.xla_extension' has no attribute 'GpuAllocatorConfig'
[2024-04-15 09:51:10,953][jax._src.xla_bridge][INFO] - Unable to initialize backend 'tpu': INTERNAL: Failed to open libtpu.so: dlopen(libtpu.so, 0x0001): tried: 'libtpu.so' (no such file), '/System/Volumes/Preboot/Cryptexes/OSlibtpu.so' (no such file), '/Users/ajgeorge/anaconda3/envs/sis/lib/python3.11/site-packages/jaxlib/../../../libtpu.so' (no such file), '/Users/ajgeorge/anaconda3/envs/sis/bin/../lib/libtpu.so' (no such file), '/usr/lib/libtpu.so' (no such file, not in dyld cache), 'libtpu.so' (no such file), '/usr/local/lib/libtpu.so' (no such file), '/usr/lib/libtpu.so' (no such file, not in dyld cache)
[2024-04-15 09:51:11,068][root][INFO] - Checkpoint directory: /Users/ajgeorge/python/sis/logs/2024-04-15/09-51-02/ckpt
[2024-04-15 09:51:15,062][root][CRITICAL] - Error in call to target 'stint_sampler.stint.sis.half_sis':
InstantiationException('Error in call to target \'stint_sampler.stint.linearInterpolants.linear\':\nUnboundLocalError("cannot access local variable \'g\' where it is not associated with a value")\nfull_key: interpolant')
full_key: solver
Traceback (most recent call last):
  File "/Users/ajgeorge/anaconda3/envs/sis/lib/python3.11/site-packages/hydra/_internal/instantiate/_instantiate2.py", line 92, in _call_target
    return _target_(*args, **kwargs)
           ^^^^^^^^^^^^^^^^^^^^^^^^^
  File "/Users/ajgeorge/python/sis/stint_sampler/stint/linearInterpolants.py", line 7, in linear
    return g,r
           ^
UnboundLocalError: cannot access local variable 'g' where it is not associated with a value
The above exception was the direct cause of the following exception:
Traceback (most recent call last):
  File "/Users/ajgeorge/anaconda3/envs/sis/lib/python3.11/site-packages/hydra/_internal/instantiate/_instantiate2.py", line 92, in _call_target
    return _target_(*args, **kwargs)
           ^^^^^^^^^^^^^^^^^^^^^^^^^
  File "/Users/ajgeorge/python/sis/stint_sampler/stint/sis.py", line 104, in __init__
    self.intrplnt = linearInterpolant(*call(self.cfg.interpolant))
                                       ^^^^^^^^^^^^^^^^^^^^^^^^^^
  File "/Users/ajgeorge/anaconda3/envs/sis/lib/python3.11/site-packages/hydra/_internal/instantiate/_instantiate2.py", line 226, in instantiate
    return instantiate_node(
           ^^^^^^^^^^^^^^^^^
  File "/Users/ajgeorge/anaconda3/envs/sis/lib/python3.11/site-packages/hydra/_internal/instantiate/_instantiate2.py", line 347, in instantiate_node
    return _call_target(_target_, partial, args, kwargs, full_key)
           ^^^^^^^^^^^^^^^^^^^^^^^^^^^^^^^^^^^^^^^^^^^^^^^^^^^^^^^
  File "/Users/ajgeorge/anaconda3/envs/sis/lib/python3.11/site-packages/hydra/_internal/instantiate/_instantiate2.py", line 97, in _call_target
    raise InstantiationException(msg) from e
hydra.errors.InstantiationException: Error in call to target 'stint_sampler.stint.linearInterpolants.linear':
UnboundLocalError("cannot access local variable 'g' where it is not associated with a value")
full_key: interpolant
The above exception was the direct cause of the following exception:
Traceback (most recent call last):
  File "/Users/ajgeorge/python/sis/main.py", line 72, in main
    sampler = instantiate(cfg.solver, cfg)
              ^^^^^^^^^^^^^^^^^^^^^^^^^^^^
  File "/Users/ajgeorge/anaconda3/envs/sis/lib/python3.11/site-packages/hydra/_internal/instantiate/_instantiate2.py", line 226, in instantiate
    return instantiate_node(
           ^^^^^^^^^^^^^^^^^
  File "/Users/ajgeorge/anaconda3/envs/sis/lib/python3.11/site-packages/hydra/_internal/instantiate/_instantiate2.py", line 347, in instantiate_node
    return _call_target(_target_, partial, args, kwargs, full_key)
           ^^^^^^^^^^^^^^^^^^^^^^^^^^^^^^^^^^^^^^^^^^^^^^^^^^^^^^^
  File "/Users/ajgeorge/anaconda3/envs/sis/lib/python3.11/site-packages/hydra/_internal/instantiate/_instantiate2.py", line 97, in _call_target
    raise InstantiationException(msg) from e
hydra.errors.InstantiationException: Error in call to target 'stint_sampler.stint.sis.half_sis':
InstantiationException('Error in call to target \'stint_sampler.stint.linearInterpolants.linear\':\nUnboundLocalError("cannot access local variable \'g\' where it is not associated with a value")\nfull_key: interpolant')
full_key: solver